package testexception;

import java.util.Scanner;

public class TestException {

	public static void main(String[] args) {

      /*
       * try
       * catch 
       * finally 
       * throw
       * throws
       */
		
		Scanner scanner = new Scanner(System.in);
		
	int dividant =scanner.nextInt();
	int divisor = scanner.nextInt();
	
		
	try {
		int result = dividant/divisor;
		System.out.println("The result is : "+  result);
		
	} catch (ArithmeticException e) {
	System.out.println("This is from catch block : "+ e.getMessage());
	}
		

	}

}
