package testexception;

import java.util.Scanner;

public class TestException {

	public static void main(String[] args) {

      /*
       * try
       * catch 
       * finally 
       * throw
       * throws
       */
		
//		Scanner scanner = new Scanner(System.in);
//		
//	int dividant =scanner.nextInt();
//	int divisor = scanner.nextInt();
	
		
//	try {
//		int result = dividant/divisor;
//		System.out.println("The result is : "+  result);
//		
//	} catch (ArithmeticException e) {
//	System.out.println("This is from catch block : "+ e.getMessage());
//	}
//		

		
		int array[]= new int[5];
	
		try {
			//array[6]=25/0;
			
			array[6]=10;
		} catch ( ArithmeticException e) {
			System.out.println("This is from ArithmeticException  block : " + e.getMessage());
		} catch (ArrayIndexOutOfBoundsException e) {
			System.out.println("This is from ArrayIndexOutOfBoundsException  block : " + e.getMessage());

		}
		
	}

}
